Workbook

Sheet Assumptions
A1: AIstudy - Financial Model Assumptions (v2, no chat)
A2: Yellow = editable input. Blue = computed. All money USD.
A3: DeepSeek V4 Flash pricing (per 1M tokens)
A4: Parameter | B4: Value | C4: Notes
A5: Input price (cache miss) | B5: 0.14 | C5: $ per 1M input tokens
A6: Input price (cache hit) | B6: 0.0028 | C6: $ per 1M input tokens
A7: Output price | B7: 0.28 | C7: $ per 1M output tokens
A8: Cache hit rate | B8: 0 | C8: share of input tokens billed at hit price
A9: Document lengths (tokens per upload)
A10: Length | B10: Tokens | C10: Notes
A11: Short PDF (~5 pages) | B11: 3300
A12: Medium PDF (~20 pages) | B12: 13300
A13: Long PDF (~60 pages) | B13: 40000
A14: Slides deck (~40 slides) | B14: 2000
A15: Upload mix (share of uploads, must sum to 1)
A16: Length | B16: Share
A17: Short PDF (~5 pages) | B17: 0.3
A18: Medium PDF (~20 pages) | B18: 0.4
A19: Long PDF (~60 pages) | B19: 0.2
A20: Slides deck (~40 slides) | B20: 0.1
A21: AI action token multipliers
A22: Action | B22: Input x doc | C22: Output x doc | D22: Notes
A23: Create note | B23: 1 | C23: 0.35 | D23: reads full doc, writes condensed notes
A24: Generate flashcards | B24: 1.5 | C24: 0.9 | D24: doc re-sent for chunking + card text
A25: Generate quiz | B25: 2 | C25: 1 | D25: doc + questions + explanations
A26: Study All flashcards (folder) | B26: 1.5 | C26: 0.9 | D26: per doc, x docs per folder
A27: Study All quiz (folder) | B27: 2 | C27: 1 | D27: per doc, x docs per folder
A28: Essay grading | B28: 1.5 | C28: 0.7 | D28: essay + rubric + feedback
A29: Docs per folder | B29: 5 | C29: folder actions multiply by this
A30: Lifetime page views per generated asset
A31: Action | B31: Views | C31: Notes
A32: Create note | B32: 12 | C32: reopened while studying
A33: Generate flashcards | B33: 15 | C33: drilled repeatedly before exams
A34: Generate quiz | B34: 4 | C34: retake attempts
A35: Study All flashcards (folder) | B35: 15 | C35: folder drills
A36: Study All quiz (folder) | B36: 4 | C36: folder retakes
A37: Essay grading | B37: 2 | C37: grade + one review
A38: Ad revenue (Google Ads, CPM range $2.00 - $8.00)
A39: Parameter | B39: Value | C39: Notes
A40: Ad slots per page | B40: 2 | C40: no rotation: 1 action = 1 page view
...

Sheet Cost Per Action
A1: AI cost per action by document length
A2: Cost = (in-mult x doc-tokens x eff-input-price + out-mult x doc-tokens x output-price) / 1M. Folder actions x docs per folder.
A3: Action | B3: Short | C3: Medium | D3: Long | E3: Slides | F3: Weighted avg
A4: Create note | B4: =(Assumptions!B23*Assumptions!B11*Assumptions!B59+Assumptions!C23*Assumptions!B11*Assumptions!B7)/1000000 | C4: =(Assumptions!B23*Assumptions!B12*Assumptions!B59+Assumptions!C23*Assumptions!B12*Assumptions!B7)/1000000 | D4: =(Assumptions!B23*Assumptions!B13*Assumptions!B59+Assumptions!C23*Assumptions!B13*Assumptions!B7)/1000000 | E4: =(Assumptions!B23*Assumptions!B14*Assumptions!B59+Assumptions!C23*Assumptions!B14*Assumptions!B7)/1000000 | F4: =B4*Assumptions!B17+C4*Assumptions!B18+D4*Assumptions!B19+E4*Assumptions!B20
A5: Generate flashcards | B5: =(Assumptions!B24*Assumptions!B11*Assumptions!B59+Assumptions!C24*Assumptions!B11*Assumptions!B7)/1000000 | C5: =(Assumptions!B24*Assumptions!B12*Assumptions!B59+Assumptions!C24*Assumptions!B12*Assumptions!B7)/1000000 | D5: =(Assumptions!B24*Assumptions!B13*Assumptions!B59+Assumptions!C24*Assumptions!B13*Assumptions!B7)/1000000 | E5: =(Assumptions!B24*Assumptions!B14*Assumptions!B59+Assumptions!C24*Assumptions!B14*Assumptions!B7)/1000000 | F5: =B5*Assumptions!B17+C5*Assumptions!B18+D5*Assumptions!B19+E5*Assumptions!B20
A6: Generate quiz | B6: =(Assumptions!B25*Assumptions!B11*Assumptions!B59+Assumptions!C25*Assumptions!B11*Assumptions!B7)/1000000 | C6: =(Assumptions!B25*Assumptions!B12*Assumptions!B59+Assumptions!C25*Assumptions!B12*Assumptions!B7)/1000000 | D6: =(Assumptions!B25*Assumptions!B13*Assumptions!B59+Assumptions!C25*Assumptions!B13*Assumptions!B7)/1000000 | E6: =(Assumptions!B25*Assumptions!B14*Assumptions!B59+Assumptions!C25*Assumptions!B14*Assumptions!B7)/1000000 | F6: =B6*Assumptions!B17+C6*Assumptions!B18+D6*Assumptions!B19+E6*Assumptions!B20
A7: Study All flashcards (folder) | B7: =(Assumptions!B26*Assumptions!B11*Assumptions!B59+Assumptions!C26*Assumptions!B11*Assumptions!B7)/1000000*Assumptions!B29 | C7: =(Assumptions!B26*Assumptions!B12*Assumptions!B59+Assumptions!C26*Assumptions!B12*Assumptions!B7)/1000000*Assumptions!B29 | D7: =(Assumptions!B26*Assumptions!B13*Assumptions!B59+Assumptions!C26*Assumptions!B13*Assumptions!B7)/1000000*Assumptions!B29 | E7: =(Assumptions!B26*Assumptions!B14*Assumptions!B59+Assumptions!C26*Assumptions!B14*Assumptions!B7)/1000000*Assumptions!B29 | F7: =B7*Assumptions!B17+C7*Assumptions!B18+D7*Assumptions!B19+E7*Assumptions!B20
A8: Study All quiz (folder) | B8: =(Assumptions!B27*Assumptions!B11*Assumptions!B59+Assumptions!C27*Assumptions!B11*Assumptions!B7)/1000000*Assumptions!B29 | C8: =(Assumptions!B27*Assumptions!B12*Assumptions!B59+Assumptions!C27*Assumptions!B12*Assumptions!B7)/1000000*Assumptions!B29 | D8: =(Assumptions!B27*Assumptions!B13*Assumptions!B59+Assumptions!C27*Assumptions!B13*Assumptions!B7)/1000000*Assumptions!B29 | E8: =(Assumptions!B27*Assumptions!B14*Assumptions!B59+Assumptions!C27*Assumptions!B14*Assumptions!B7)/1000000*Assumptions!B29 | F8: =B8*Assumptions!B17+C8*Assumptions!B18+D8*Assumptions!B19+E8*Assumptions!B20
A9: Essay grading | B9: =(Assumptions!B28*Assumptions!B11*Assumptions!B59+Assumptions!C28*Assumptions!B11*Assumptions!B7)/1000000 | C9: =(Assumptions!B28*Assumptions!B12*Assumptions!B59+Assumptions!C28*Assumptions!B12*Assumptions!B7)/1000000 | D9: =(Assumptions!B28*Assumptions!B13*Assumptions!B59+Assumptions!C28*Assumptions!B13*Assumptions!B7)/1000000 | E9: =(Assumptions!B28*Assumptions!B14*Assumptions!B59+Assumptions!C28*Assumptions!B14*Assumptions!B7)/1000000 | F9: =B9*Assumptions!B17+C9*Assumptions!B18+D9*Assumptions!B19+E9*Assumptions!B20

Sheet Unit Economics
A1: Unit economics per action (CPM $2 vs $8)
A2: Weighted avg cost across upload mix. Revenue per action is flat across actions (1:1 action-to-ad).
A3: Action | B3: Avg cost | C3: Revenue @$2 | D3: Revenue @$8 | E3: Profit @$2 | F3: Profit @$8 | G3: Break-even CPM ($)
A4: Create note | B4: ='Cost Per Action'!F4 | C4: =Assumptions!B32*Assumptions!B60 | D4: =Assumptions!B32*Assumptions!B61 | E4: =C4-B4 | F4: =D4-B4 | G4: =B4*1000/(Assumptions!B32*Assumptions!B40*IF(Assumptions!B46,Assumptions!B44,Assumptions!B43)*(1-Assumptions!B45))
A5: Generate flashcards | B5: ='Cost Per Action'!F5 | C5: =Assumptions!B33*Assumptions!B60 | D5: =Assumptions!B33*Assumptions!B61 | E5: =C5-B5 | F5: =D5-B5 | G5: =B5*1000/(Assumptions!B33*Assumptions!B40*IF(Assumptions!B46,Assumptions!B44,Assumptions!B43)*(1-Assumptions!B45))
A6: Generate quiz | B6: ='Cost Per Action'!F6 | C6: =Assumptions!B34*Assumptions!B60 | D6: =Assumptions!B34*Assumptions!B61 | E6: =C6-B6 | F6: =D6-B6 | G6: =B6*1000/(Assumptions!B34*Assumptions!B40*IF(Assumptions!B46,Assumptions!B44,Assumptions!B43)*(1-Assumptions!B45))
A7: Study All flashcards (folder) | B7: ='Cost Per Action'!F7 | C7: =Assumptions!B35*Assumptions!B60 | D7: =Assumptions!B35*Assumptions!B61 | E7: =C7-B7 | F7: =D7-B7 | G7: =B7*1000/(Assumptions!B35*Assumptions!B40*IF(Assumptions!B46,Assumptions!B44,Assumptions!B43)*(1-Assumptions!B45))
A8: Study All quiz (folder) | B8: ='Cost Per Action'!F8 | C8: =Assumptions!B36*Assumptions!B60 | D8: =Assumptions!B36*Assumptions!B61 | E8: =C8-B8 | F8: =D8-B8 | G8: =B8*1000/(Assumptions!B36*Assumptions!B40*IF(Assumptions!B46,Assumptions!B44,Assumptions!B43)*(1-Assumptions!B45))
A9: Essay grading | B9: ='Cost Per Action'!F9 | C9: =Assumptions!B37*Assumptions!B60 | D9: =Assumptions!B37*Assumptions!B61 | E9: =C9-B9 | F9: =D9-B9 | G9: =B9*1000/(Assumptions!B37*Assumptions!B40*IF(Assumptions!B46,Assumptions!B44,Assumptions!B43)*(1-Assumptions!B45))

Sheet Usage Mix
A1: Action mix - share of daily paid actions by tier
A3: Action | B3: Heavy | C3: Moderate | D3: Light/Casual
A4: Create note | B4: 0.1 | C4: 0.1 | D4: 0.15
A5: Generate flashcards | B5: 0.15 | C5: 0.15 | D5: 0.2
A6: Generate quiz | B6: 0.1 | C6: 0.1 | D6: 0.1
A7: Study All flashcards | B7: 0.2 | C7: 0.2 | D7: 0.15
A8: Study All quiz | B8: 0.15 | C8: 0.15 | D8: 0.1
A9: Essay grading | B9: 0.1 | C9: 0.1 | D9: 0.1
A10: Total paid share | B10: =SUM(B4:B9) | C10: =SUM(C4:C9) | D10: =SUM(D4:D9)

Sheet Per-User P&L
A1: Monthly P&L per user tier (paid + free actions)
A3: Tier | B3: Paid acts/mo | C3: Free acts/mo | D3: AI cost | E3: Revenue @$2 | F3: Profit @$2 | G3: Revenue @$8 | H3: Profit @$8
A4: Heavy (3+ courses) | B4: =Assumptions!B53*Assumptions!C53 | C4: =Assumptions!D53*Assumptions!C53 | D4: =B4*('Usage Mix'!B4*'Cost Per Action'!F4+'Usage Mix'!B5*'Cost Per Action'!F5+'Usage Mix'!B6*'Cost Per Action'!F6+'Usage Mix'!B7*'Cost Per Action'!F7+'Usage Mix'!B8*'Cost Per Action'!F8+'Usage Mix'!B9*'Cost Per Action'!F9) | E4: =B4*('Usage Mix'!B4*Assumptions!B32+'Usage Mix'!B5*Assumptions!B33+'Usage Mix'!B6*Assumptions!B34+'Usage Mix'!B7*Assumptions!B35+'Usage Mix'!B8*Assumptions!B36+'Usage Mix'!B9*Assumptions!B37)*Assumptions!B60+C4*Assumptions!B60 | F4: =E4-D4 | G4: =B4*('Usage Mix'!B4*Assumptions!B32+'Usage Mix'!B5*Assumptions!B33+'Usage Mix'!B6*Assumptions!B34+'Usage Mix'!B7*Assumptions!B35+'Usage Mix'!B8*Assumptions!B36+'Usage Mix'!B9*Assumptions!B37)*Assumptions!B61+C4*Assumptions!B61 | H4: =G4-D4
A5: Moderate (2-3 courses) | B5: =Assumptions!B54*Assumptions!C54 | C5: =Assumptions!D54*Assumptions!C54 | D5: =B5*('Usage Mix'!C4*'Cost Per Action'!F4+'Usage Mix'!C5*'Cost Per Action'!F5+'Usage Mix'!C6*'Cost Per Action'!F6+'Usage Mix'!C7*'Cost Per Action'!F7+'Usage Mix'!C8*'Cost Per Action'!F8+'Usage Mix'!C9*'Cost Per Action'!F9) | E5: =B5*('Usage Mix'!C4*Assumptions!B32+'Usage Mix'!C5*Assumptions!B33+'Usage Mix'!C6*Assumptions!B34+'Usage Mix'!C7*Assumptions!B35+'Usage Mix'!C8*Assumptions!B36+'Usage Mix'!C9*Assumptions!B37)*Assumptions!B60+C5*Assumptions!B60 | F5: =E5-D5 | G5: =B5*('Usage Mix'!C4*Assumptions!B32+'Usage Mix'!C5*Assumptions!B33+'Usage Mix'!C6*Assumptions!B34+'Usage Mix'!C7*Assumptions!B35+'Usage Mix'!C8*Assumptions!B36+'Usage Mix'!C9*Assumptions!B37)*Assumptions!B61+C5*Assumptions!B61 | H5: =G5-D5
A6: Light (1-2 courses) | B6: =Assumptions!B55*Assumptions!C55 | C6: =Assumptions!D55*Assumptions!C55 | D6: =B6*('Usage Mix'!D4*'Cost Per Action'!F4+'Usage Mix'!D5*'Cost Per Action'!F5+'Usage Mix'!D6*'Cost Per Action'!F6+'Usage Mix'!D7*'Cost Per Action'!F7+'Usage Mix'!D8*'Cost Per Action'!F8+'Usage Mix'!D9*'Cost Per Action'!F9) | E6: =B6*('Usage Mix'!D4*Assumptions!B32+'Usage Mix'!D5*Assumptions!B33+'Usage Mix'!D6*Assumptions!B34+'Usage Mix'!D7*Assumptions!B35+'Usage Mix'!D8*Assumptions!B36+'Usage Mix'!D9*Assumptions!B37)*Assumptions!B60+C6*Assumptions!B60 | F6: =E6-D6 | G6: =B6*('Usage Mix'!D4*Assumptions!B32+'Usage Mix'!D5*Assumptions!B33+'Usage Mix'!D6*Assumptions!B34+'Usage Mix'!D7*Assumptions!B35+'Usage Mix'!D8*Assumptions!B36+'Usage Mix'!D9*Assumptions!B37)*Assumptions!B61+C6*Assumptions!B61 | H6: =G6-D6
A7: Casual | B7: =Assumptions!B56*Assumptions!C56 | C7: =Assumptions!D56*Assumptions!C56 | D7: =B7*('Usage Mix'!D4*'Cost Per Action'!F4+'Usage Mix'!D5*'Cost Per Action'!F5+'Usage Mix'!D6*'Cost Per Action'!F6+'Usage Mix'!D7*'Cost Per Action'!F7+'Usage Mix'!D8*'Cost Per Action'!F8+'Usage Mix'!D9*'Cost Per Action'!F9) | E7: =B7*('Usage Mix'!D4*Assumptions!B32+'Usage Mix'!D5*Assumptions!B33+'Usage Mix'!D6*Assumptions!B34+'Usage Mix'!D7*Assumptions!B35+'Usage Mix'!D8*Assumptions!B36+'Usage Mix'!D9*Assumptions!B37)*Assumptions!B60+C7*Assumptions!B60 | F7: =E7-D7 | G7: =B7*('Usage Mix'!D4*Assumptions!B32+'Usage Mix'!D5*Assumptions!B33+'Usage Mix'!D6*Assumptions!B34+'Usage Mix'!D7*Assumptions!B35+'Usage Mix'!D8*Assumptions!B36+'Usage Mix'!D9*Assumptions!B37)*Assumptions!B61+C7*Assumptions!B61 | H7: =G7-D7

Sheet Scale Model
A1: Scale model - total business P&L
A2: Profit = ad revenue - AI cost - hosting & infra.
B3: Heavy | C3: Moderate | D3: Light | E3: Casual | F3: AI cost | G3: Rev @$2 | H3: Profit @$2 | I3: Rev @$8 | J3: Profit @$8
A5: Users (editable) | B5: 500 | C5: 1500 | D5: 4000 | E5: 10000
A7: AI cost | F7: ='Per-User P&L'!D4*B5+'Per-User P&L'!D5*C5+'Per-User P&L'!D6*D5+'Per-User P&L'!D7*E5
A8: Hosting | F8: =Assumptions!B49+Assumptions!B50*SUM(B5:E5)
A9: Revenue @$2 | F9: ='Per-User P&L'!E4*B5+'Per-User P&L'!E5*C5+'Per-User P&L'!E6*D5+'Per-User P&L'!E7*E5
A10: Profit @$2 | F10: =F9-F7-F8
A11: Revenue @$8 | F11: ='Per-User P&L'!G4*B5+'Per-User P&L'!G5*C5+'Per-User P&L'!G6*D5+'Per-User P&L'!G7*E5
A12: Profit @$8 | F12: =F11-F7-F8
A13: Total users | F13: =SUM(B5:E5)
A15: 12-month projection (5% monthly user growth)
A16: Month | B16: Heavy | C16: Moderate | D16: Light | E16: Casual | F16: Net profit @$2 | G16: Net profit @$8 | H16: Rev @$8
A17: Month 1 | B17: =B5 | C17: =C5 | D17: =D5 | E17: =E5 | F17: ='Per-User P&L'!E4*B17+'Per-User P&L'!E5*C17+'Per-User P&L'!E6*D17+'Per-User P&L'!E7*E17-'Per-User P&L'!D4*B17+'Per-User P&L'!D5*C17+'Per-User P&L'!D6*D17+'Per-User P&L'!D7*E17-(Assumptions!B49+Assumptions!B50*SUM(B17:E17)) | G17: ='Per-User P&L'!G4*B17+'Per-User P&L'!G5*C17+'Per-User P&L'!G6*D17+'Per-User P&L'!G7*E17-'Per-User P&L'!D4*B17+'Per-User P&L'!D5*C17+'Per-User P&L'!D6*D17+'Per-User P&L'!D7*E17-(Assumptions!B49+Assumptions!B50*SUM(B17:E17)) | H17: ='Per-User P&L'!G4*B17+'Per-User P&L'!G5*C17+'Per-User P&L'!G6*D17+'Per-User P&L'!G7*E17
A18: Month 2 | B18: =B5*(1+0.05)^1 | C18: =C5*(1+0.05)^1 | D18: =D5*(1+0.05)^1 | E18: =E5*(1+0.05)^1 | F18: ='Per-User P&L'!E4*B18+'Per-User P&L'!E5*C18+'Per-User P&L'!E6*D18+'Per-User P&L'!E7*E18-'Per-User P&L'!D4*B18+'Per-User P&L'!D5*C18+'Per-User P&L'!D6*D18+'Per-User P&L'!D7*E18-(Assumptions!B49+Assumptions!B50*SUM(B18:E18)) | G18: ='Per-User P&L'!G4*B18+'Per-User P&L'!G5*C18+'Per-User P&L'!G6*D18+'Per-User P&L'!G7*E18-'Per-User P&L'!D4*B18+'Per-User P&L'!D5*C18+'Per-User P&L'!D6*D18+'Per-User P&L'!D7*E18-(Assumptions!B49+Assumptions!B50*SUM(B18:E18)) | H18: ='Per-User P&L'!G4*B18+'Per-User P&L'!G5*C18+'Per-User P&L'!G6*D18+'Per-User P&L'!G7*E18
A19: Month 3 | B19: =B5*(1+0.05)^2 | C19: =C5*(1+0.05)^2 | D19: =D5*(1+0.05)^2 | E19: =E5*(1+0.05)^2 | F19: ='Per-User P&L'!E4*B19+'Per-User P&L'!E5*C19+'Per-User P&L'!E6*D19+'Per-User P&L'!E7*E19-'Per-User P&L'!D4*B19+'Per-User P&L'!D5*C19+'Per-User P&L'!D6*D19+'Per-User P&L'!D7*E19-(Assumptions!B49+Assumptions!B50*SUM(B19:E19)) | G19: ='Per-User P&L'!G4*B19+'Per-User P&L'!G5*C19+'Per-User P&L'!G6*D19+'Per-User P&L'!G7*E19-'Per-User P&L'!D4*B19+'Per-User P&L'!D5*C19+'Per-User P&L'!D6*D19+'Per-User P&L'!D7*E19-(Assumptions!B49+Assumptions!B50*SUM(B19:E19)) | H19: ='Per-User P&L'!G4*B19+'Per-User P&L'!G5*C19+'Per-User P&L'!G6*D19+'Per-User P&L'!G7*E19
A20: Month 4 | B20: =B5*(1+0.05)^3 | C20: =C5*(1+0.05)^3 | D20: =D5*(1+0.05)^3 | E20: =E5*(1+0.05)^3 | F20: ='Per-User P&L'!E4*B20+'Per-User P&L'!E5*C20+'Per-User P&L'!E6*D20+'Per-User P&L'!E7*E20-'Per-User P&L'!D4*B20+'Per-User P&L'!D5*C20+'Per-User P&L'!D6*D20+'Per-User P&L'!D7*E20-(Assumptions!B49+Assumptions!B50*SUM(B20:E20)) | G20: ='Per-User P&L'!G4*B20+'Per-User P&L'!G5*C20+'Per-User P&L'!G6*D20+'Per-User P&L'!G7*E20-'Per-User P&L'!D4*B20+'Per-User P&L'!D5*C20+'Per-User P&L'!D6*D20+'Per-User P&L'!D7*E20-(Assumptions!B49+Assumptions!B50*SUM(B20:E20)) | H20: ='Per-User P&L'!G4*B20+'Per-User P&L'!G5*C20+'Per-User P&L'!G6*D20+'Per-User P&L'!G7*E20
A21: Month 5 | B21: =B5*(1+0.05)^4 | C21: =C5*(1+0.05)^4 | D21: =D5*(1+0.05)^4 | E21: =E5*(1+0.05)^4 | F21: ='Per-User P&L'!E4*B21+'Per-User P&L'!E5*C21+'Per-User P&L'!E6*D21+'Per-User P&L'!E7*E21-'Per-User P&L'!D4*B21+'Per-User P&L'!D5*C21+'Per-User P&L'!D6*D21+'Per-User P&L'!D7*E21-(Assumptions!B49+Assumptions!B50*SUM(B21:E21)) | G21: ='Per-User P&L'!G4*B21+'Per-User P&L'!G5*C21+'Per-User P&L'!G6*D21+'Per-User P&L'!G7*E21-'Per-User P&L'!D4*B21+'Per-User P&L'!D5*C21+'Per-User P&L'!D6*D21+'Per-User P&L'!D7*E21-(Assumptions!B49+Assumptions!B50*SUM(B21:E21)) | H21: ='Per-User P&L'!G4*B21+'Per-User P&L'!G5*C21+'Per-User P&L'!G6*D21+'Per-User P&L'!G7*E21
A22: Month 6 | B22: =B5*(1+0.05)^5 | C22: =C5*(1+0.05)^5 | D22: =D5*(1+0.05)^5 | E22: =E5*(1+0.05)^5 | F22: ='Per-User P&L'!E4*B22+'Per-User P&L'!E5*C22+'Per-User P&L'!E6*D22+'Per-User P&L'!E7*E22-'Per-User P&L'!D4*B22+'Per-User P&L'!D5*C22+'Per-User P&L'!D6*D22+'Per-User P&L'!D7*E22-(Assumptions!B49+Assumptions!B50*SUM(B22:E22)) | G22: ='Per-User P&L'!G4*B22+'Per-User P&L'!G5*C22+'Per-User P&L'!G6*D22+'Per-User P&L'!G7*E22-'Per-User P&L'!D4*B22+'Per-User P&L'!D5*C22+'Per-User P&L'!D6*D22+'Per-User P&L'!D7*E22-(Assumptions!B49+Assumptions!B50*SUM(B22:E22)) | H22: ='Per-User P&L'!G4*B22+'Per-User P&L'!G5*C22+'Per-User P&L'!G6*D22+'Per-User P&L'!G7*E22
A23: Month 7 | B23: =B5*(1+0.05)^6 | C23: =C5*(1+0.05)^6 | D23: =D5*(1+0.05)^6 | E23: =E5*(1+0.05)^6 | F23: ='Per-User P&L'!E4*B23+'Per-User P&L'!E5*C23+'Per-User P&L'!E6*D23+'Per-User P&L'!E7*E23-'Per-User P&L'!D4*B23+'Per-User P&L'!D5*C23+'Per-User P&L'!D6*D23+'Per-User P&L'!D7*E23-(Assumptions!B49+Assumptions!B50*SUM(B23:E23)) | G23: ='Per-User P&L'!G4*B23+'Per-User P&L'!G5*C23+'Per-User P&L'!G6*D23+'Per-User P&L'!G7*E23-'Per-User P&L'!D4*B23+'Per-User P&L'!D5*C23+'Per-User P&L'!D6*D23+'Per-User P&L'!D7*E23-(Assumptions!B49+Assumptions!B50*SUM(B23:E23)) | H23: ='Per-User P&L'!G4*B23+'Per-User P&L'!G5*C23+'Per-User P&L'!G6*D23+'Per-User P&L'!G7*E23
A24: Month 8 | B24: =B5*(1+0.05)^7 | C24: =C5*(1+0.05)^7 | D24: =D5*(1+0.05)^7 | E24: =E5*(1+0.05)^7 | F24: ='Per-User P&L'!E4*B24+'Per-User P&L'!E5*C24+'Per-User P&L'!E6*D24+'Per-User P&L'!E7*E24-'Per-User P&L'!D4*B24+'Per-User P&L'!D5*C24+'Per-User P&L'!D6*D24+'Per-User P&L'!D7*E24-(Assumptions!B49+Assumptions!B50*SUM(B24:E24)) | G24: ='Per-User P&L'!G4*B24+'Per-User P&L'!G5*C24+'Per-User P&L'!G6*D24+'Per-User P&L'!G7*E24-'Per-User P&L'!D4*B24+'Per-User P&L'!D5*C24+'Per-User P&L'!D6*D24+'Per-User P&L'!D7*E24-(Assumptions!B49+Assumptions!B50*SUM(B24:E24)) | H24: ='Per-User P&L'!G4*B24+'Per-User P&L'!G5*C24+'Per-User P&L'!G6*D24+'Per-User P&L'!G7*E24
A25: Month 9 | B25: =B5*(1+0.05)^8 | C25: =C5*(1+0.05)^8 | D25: =D5*(1+0.05)^8 | E25: =E5*(1+0.05)^8 | F25: ='Per-User P&L'!E4*B25+'Per-User P&L'!E5*C25+'Per-User P&L'!E6*D25+'Per-User P&L'!E7*E25-'Per-User P&L'!D4*B25+'Per-User P&L'!D5*C25+'Per-User P&L'!D6*D25+'Per-User P&L'!D7*E25-(Assumptions!B49+Assumptions!B50*SUM(B25:E25)) | G25: ='Per-User P&L'!G4*B25+'Per-User P&L'!G5*C25+'Per-User P&L'!G6*D25+'Per-User P&L'!G7*E25-'Per-User P&L'!D4*B25+'Per-User P&L'!D5*C25+'Per-User P&L'!D6*D25+'Per-User P&L'!D7*E25-(Assumptions!B49+Assumptions!B50*SUM(B25:E25)) | H25: ='Per-User P&L'!G4*B25+'Per-User P&L'!G5*C25+'Per-User P&L'!G6*D25+'Per-User P&L'!G7*E25
A26: Month 10 | B26: =B5*(1+0.05)^9 | C26: =C5*(1+0.05)^9 | D26: =D5*(1+0.05)^9 | E26: =E5*(1+0.05)^9 | F26: ='Per-User P&L'!E4*B26+'Per-User P&L'!E5*C26+'Per-User P&L'!E6*D26+'Per-User P&L'!E7*E26-'Per-User P&L'!D4*B26+'Per-User P&L'!D5*C26+'Per-User P&L'!D6*D26+'Per-User P&L'!D7*E26-(Assumptions!B49+Assumptions!B50*SUM(B26:E26)) | G26: ='Per-User P&L'!G4*B26+'Per-User P&L'!G5*C26+'Per-User P&L'!G6*D26+'Per-User P&L'!G7*E26-'Per-User P&L'!D4*B26+'Per-User P&L'!D5*C26+'Per-User P&L'!D6*D26+'Per-User P&L'!D7*E26-(Assumptions!B49+Assumptions!B50*SUM(B26:E26)) | H26: ='Per-User P&L'!G4*B26+'Per-User P&L'!G5*C26+'Per-User P&L'!G6*D26+'Per-User P&L'!G7*E26
A27: Month 11 | B27: =B5*(1+0.05)^10 | C27: =C5*(1+0.05)^10 | D27: =D5*(1+0.05)^10 | E27: =E5*(1+0.05)^10 | F27: ='Per-User P&L'!E4*B27+'Per-User P&L'!E5*C27+'Per-User P&L'!E6*D27+'Per-User P&L'!E7*E27-'Per-User P&L'!D4*B27+'Per-User P&L'!D5*C27+'Per-User P&L'!D6*D27+'Per-User P&L'!D7*E27-(Assumptions!B49+Assumptions!B50*SUM(B27:E27)) | G27: ='Per-User P&L'!G4*B27+'Per-User P&L'!G5*C27+'Per-User P&L'!G6*D27+'Per-User P&L'!G7*E27-'Per-User P&L'!D4*B27+'Per-User P&L'!D5*C27+'Per-User P&L'!D6*D27+'Per-User P&L'!D7*E27-(Assumptions!B49+Assumptions!B50*SUM(B27:E27)) | H27: ='Per-User P&L'!G4*B27+'Per-User P&L'!G5*C27+'Per-User P&L'!G6*D27+'Per-User P&L'!G7*E27
A28: Month 12 | B28: =B5*(1+0.05)^11 | C28: =C5*(1+0.05)^11 | D28: =D5*(1+0.05)^11 | E28: =E5*(1+0.05)^11 | F28: ='Per-User P&L'!E4*B28+'Per-User P&L'!E5*C28+'Per-User P&L'!E6*D28+'Per-User P&L'!E7*E28-'Per-User P&L'!D4*B28+'Per-User P&L'!D5*C28+'Per-User P&L'!D6*D28+'Per-User P&L'!D7*E28-(Assumptions!B49+Assumptions!B50*SUM(B28:E28)) | G28: ='Per-User P&L'!G4*B28+'Per-User P&L'!G5*C28+'Per-User P&L'!G6*D28+'Per-User P&L'!G7*E28-'Per-User P&L'!D4*B28+'Per-User P&L'!D5*C28+'Per-User P&L'!D6*D28+'Per-User P&L'!D7*E28-(Assumptions!B49+Assumptions!B50*SUM(B28:E28)) | H28: ='Per-User P&L'!G4*B28+'Per-User P&L'!G5*C28+'Per-User P&L'!G6*D28+'Per-User P&L'!G7*E28
A29: Year 1 total | F29: =SUM(F17:F28) | G29: =SUM(G17:G28) | H29: =SUM(H17:H28)

Sheet Break-Even
A1: Break-even analysis
A3: Revenue per page view across Google Ads CPM range
A4: CPM ($) | B4: Rev/view sticky (95%) | C4: Rev/view standard (60%)
A5: 2 | B5: =A5*Assumptions!B40*Assumptions!B44*(1-Assumptions!B45)/1000 | C5: =A5*Assumptions!B40*Assumptions!B43*(1-Assumptions!B45)/1000
A6: 3 | B6: =A6*Assumptions!B40*Assumptions!B44*(1-Assumptions!B45)/1000 | C6: =A6*Assumptions!B40*Assumptions!B43*(1-Assumptions!B45)/1000
A7: 4 | B7: =A7*Assumptions!B40*Assumptions!B44*(1-Assumptions!B45)/1000 | C7: =A7*Assumptions!B40*Assumptions!B43*(1-Assumptions!B45)/1000
A8: 5 | B8: =A8*Assumptions!B40*Assumptions!B44*(1-Assumptions!B45)/1000 | C8: =A8*Assumptions!B40*Assumptions!B43*(1-Assumptions!B45)/1000
A9: 6 | B9: =A9*Assumptions!B40*Assumptions!B44*(1-Assumptions!B45)/1000 | C9: =A9*Assumptions!B40*Assumptions!B43*(1-Assumptions!B45)/1000
A10: 7 | B10: =A10*Assumptions!B40*Assumptions!B44*(1-Assumptions!B45)/1000 | C10: =A10*Assumptions!B40*Assumptions!B43*(1-Assumptions!B45)/1000
A11: 8 | B11: =A11*Assumptions!B40*Assumptions!B44*(1-Assumptions!B45)/1000 | C11: =A11*Assumptions!B40*Assumptions!B43*(1-Assumptions!B45)/1000
A13: Break-even CPM per action (2 slots, sticky)
A14: Action | B14: Avg cost | C14: Break-even CPM ($)
A15: Create note | B15: ='Cost Per Action'!F4 | C15: ='Unit Economics'!G4
A16: Generate flashcards | B16: ='Cost Per Action'!F5 | C16: ='Unit Economics'!G5
A17: Generate quiz | B17: ='Cost Per Action'!F6 | C17: ='Unit Economics'!G6
A18: Study All flashcards (folder) | B18: ='Cost Per Action'!F7 | C18: ='Unit Economics'!G7
A19: Study All quiz (folder) | B19: ='Cost Per Action'!F8 | C19: ='Unit Economics'!G8
A20: Essay grading | B20: ='Cost Per Action'!F9 | C20: ='Unit Economics'!G9

Sheet Scenarios
A1: Heavy user monthly profit: CPM x ad slots
A2: Heavy user = 300 paid (x lifetime views) + 75 free game views/month. AI cost from Per-User P&L.
A3: CPM ($) | B3: 1 slot | C3: 2 slots | D3: 3 slots
A4: 2 | B4: =('Per-User P&L'!B4*('Usage Mix'!B4*Assumptions!B32+'Usage Mix'!B5*Assumptions!B33+'Usage Mix'!B6*Assumptions!B34+'Usage Mix'!B7*Assumptions!B35+'Usage Mix'!B8*Assumptions!B36+'Usage Mix'!B9*Assumptions!B37)+'Per-User P&L'!C4)*A4*1*IF(Assumptions!B46,Assumptions!B44,Assumptions!B43)*(1-Assumptions!B45)/1000-'Per-User P&L'!D4 | C4: =('Per-User P&L'!B4*('Usage Mix'!B4*Assumptions!B32+'Usage Mix'!B5*Assumptions!B33+'Usage Mix'!B6*Assumptions!B34+'Usage Mix'!B7*Assumptions!B35+'Usage Mix'!B8*Assumptions!B36+'Usage Mix'!B9*Assumptions!B37)+'Per-User P&L'!C4)*A4*2*IF(Assumptions!B46,Assumptions!B44,Assumptions!B43)*(1-Assumptions!B45)/1000-'Per-User P&L'!D4 | D4: =('Per-User P&L'!B4*('Usage Mix'!B4*Assumptions!B32+'Usage Mix'!B5*Assumptions!B33+'Usage Mix'!B6*Assumptions!B34+'Usage Mix'!B7*Assumptions!B35+'Usage Mix'!B8*Assumptions!B36+'Usage Mix'!B9*Assumptions!B37)+'Per-User P&L'!C4)*A4*3*IF(Assumptions!B46,Assumptions!B44,Assumptions!B43)*(1-Assumptions!B45)/1000-'Per-User P&L'!D4
A5: 4 | B5: =('Per-User P&L'!B4*('Usage Mix'!B4*Assumptions!B32+'Usage Mix'!B5*Assumptions!B33+'Usage Mix'!B6*Assumptions!B34+'Usage Mix'!B7*Assumptions!B35+'Usage Mix'!B8*Assumptions!B36+'Usage Mix'!B9*Assumptions!B37)+'Per-User P&L'!C4)*A5*1*IF(Assumptions!B46,Assumptions!B44,Assumptions!B43)*(1-Assumptions!B45)/1000-'Per-User P&L'!D4 | C5: =('Per-User P&L'!B4*('Usage Mix'!B4*Assumptions!B32+'Usage Mix'!B5*Assumptions!B33+'Usage Mix'!B6*Assumptions!B34+'Usage Mix'!B7*Assumptions!B35+'Usage Mix'!B8*Assumptions!B36+'Usage Mix'!B9*Assumptions!B37)+'Per-User P&L'!C4)*A5*2*IF(Assumptions!B46,Assumptions!B44,Assumptions!B43)*(1-Assumptions!B45)/1000-'Per-User P&L'!D4 | D5: =('Per-User P&L'!B4*('Usage Mix'!B4*Assumptions!B32+'Usage Mix'!B5*Assumptions!B33+'Usage Mix'!B6*Assumptions!B34+'Usage Mix'!B7*Assumptions!B35+'Usage Mix'!B8*Assumptions!B36+'Usage Mix'!B9*Assumptions!B37)+'Per-User P&L'!C4)*A5*3*IF(Assumptions!B46,Assumptions!B44,Assumptions!B43)*(1-Assumptions!B45)/1000-'Per-User P&L'!D4
A6: 6 | B6: =('Per-User P&L'!B4*('Usage Mix'!B4*Assumptions!B32+'Usage Mix'!B5*Assumptions!B33+'Usage Mix'!B6*Assumptions!B34+'Usage Mix'!B7*Assumptions!B35+'Usage Mix'!B8*Assumptions!B36+'Usage Mix'!B9*Assumptions!B37)+'Per-User P&L'!C4)*A6*1*IF(Assumptions!B46,Assumptions!B44,Assumptions!B43)*(1-Assumptions!B45)/1000-'Per-User P&L'!D4 | C6: =('Per-User P&L'!B4*('Usage Mix'!B4*Assumptions!B32+'Usage Mix'!B5*Assumptions!B33+'Usage Mix'!B6*Assumptions!B34+'Usage Mix'!B7*Assumptions!B35+'Usage Mix'!B8*Assumptions!B36+'Usage Mix'!B9*Assumptions!B37)+'Per-User P&L'!C4)*A6*2*IF(Assumptions!B46,Assumptions!B44,Assumptions!B43)*(1-Assumptions!B45)/1000-'Per-User P&L'!D4 | D6: =('Per-User P&L'!B4*('Usage Mix'!B4*Assumptions!B32+'Usage Mix'!B5*Assumptions!B33+'Usage Mix'!B6*Assumptions!B34+'Usage Mix'!B7*Assumptions!B35+'Usage Mix'!B8*Assumptions!B36+'Usage Mix'!B9*Assumptions!B37)+'Per-User P&L'!C4)*A6*3*IF(Assumptions!B46,Assumptions!B44,Assumptions!B43)*(1-Assumptions!B45)/1000-'Per-User P&L'!D4
A7: 8 | B7: =('Per-User P&L'!B4*('Usage Mix'!B4*Assumptions!B32+'Usage Mix'!B5*Assumptions!B33+'Usage Mix'!B6*Assumptions!B34+'Usage Mix'!B7*Assumptions!B35+'Usage Mix'!B8*Assumptions!B36+'Usage Mix'!B9*Assumptions!B37)+'Per-User P&L'!C4)*A7*1*IF(Assumptions!B46,Assumptions!B44,Assumptions!B43)*(1-Assumptions!B45)/1000-'Per-User P&L'!D4 | C7: =('Per-User P&L'!B4*('Usage Mix'!B4*Assumptions!B32+'Usage Mix'!B5*Assumptions!B33+'Usage Mix'!B6*Assumptions!B34+'Usage Mix'!B7*Assumptions!B35+'Usage Mix'!B8*Assumptions!B36+'Usage Mix'!B9*Assumptions!B37)+'Per-User P&L'!C4)*A7*2*IF(Assumptions!B46,Assumptions!B44,Assumptions!B43)*(1-Assumptions!B45)/1000-'Per-User P&L'!D4 | D7: =('Per-User P&L'!B4*('Usage Mix'!B4*Assumptions!B32+'Usage Mix'!B5*Assumptions!B33+'Usage Mix'!B6*Assumptions!B34+'Usage Mix'!B7*Assumptions!B35+'Usage Mix'!B8*Assumptions!B36+'Usage Mix'!B9*Assumptions!B37)+'Per-User P&L'!C4)*A7*3*IF(Assumptions!B46,Assumptions!B44,Assumptions!B43)*(1-Assumptions!B45)/1000-'Per-User P&L'!D4
